Workbook

Sheet CONFIG
A1: CONFIGURAÇÕES (células a azul = inputs)
A3: Período | D3: Feriados (opcional)
A4: Data de referência (para mapas) | B4: 46055 | D4: Data
A6: Custos
A7: Custo por viagem (€) | B7: 12.5
A9: Taxas por hora (€)
A10: Função | B10: €/h
A11: Servente | B11: 8
A12: Canalizador | B12: 10
A13: Polivalente | B13: 10
A14: Carpinteiro de cofragem | B14: 11
A15: Pedreiro | B15: 8
A16: Armador de Ferro | B16: 12
A17: Eletricista | B17: 11
A18: Pintor | B18: 8
A23: Viagens padrão por dia da semana
A24: Dia semana (1=Seg ... 7=Dom) | B24: Viagens
A25: 1 | B25: 5
A26: 2 | B26: 3
A27: 3 | B27: 4
A28: 4 | B28: 6
A29: 5 | B29: 2
A30: 6 | B30: 0
A31: 7 | B31: 0

Sheet OBRAS
A1: LISTA DE OBRAS
A3: Obra_ID | B3: Local_ID
A4: O01 | B4: Pera I
A5: O02 | B5: Pera II
A6: O03 | B6: Fernão Ferro I
A7: O04 | B7: Fernão Ferro II
A8: O05 | B8: Sobreda
A9: O06 | B9: Montijo
A10: O07 | B10: Palmela
A11: O08 | B11: Lagoa de Albufeira
A12: O09 | B12: Sintra
A13: O10 | B13: Oeiras
A14: O11 | B14: Qta da Queimada
... A20: OFF | B20: Escritorio

Sheet FASES_DE_OBRA
A1: ID_Obra | B1: Fases de obra
A2: A | B2: A - projetos
A3: B | B3: B - abertura estaleiro
A4: C | B4: C - movimentação terras
A5: D | B5: D - estrutura
A6: E | B6: E - paredes exteriores e interiores
A7: F | B7: F - capoto/isolamento
A8: G | B8: G- eletricidade
A9: H | B9: H- aguas
A10: I | B10: I - tectos falsos
A11: J | B11: J - gás
A12: K | B12: K - carpintaria (cozinha e roupeiros)
... A23: V | B23: V - AQS e Climatização

Sheet COLABORADORES
A3: Nome | B3: Função | C3: €/h
A4: Abigail Alexandrino | B4: Servente | C4: =IFERROR(VLOOKUP(B4,CONFIG!$A$11:$B$18,2,FALSE),"") -> 8
A5: Admilson Ramos | B5: Polivalente | C5: =IFERROR(VLOOKUP(B5,CONFIG!$A$11:$B$18,2,FALSE),"") -> 10
A6: Adriano Mendes | B6: Servente | C6: =IFERROR(VLOOKUP(B6,CONFIG!$A$11:$B$18,2,FALSE),"") -> 8
A7: Afonso Rodrigo Silva | B7: Servente | C7: =IFERROR(VLOOKUP(B7,CONFIG!$A$11:$B$18,2,FALSE),"") -> 8
A8: Agmarlo de Albuquerque Ambrósio | B8: Polivalente | C8: =IFERROR(VLOOKUP(B8,CONFIG!$A$11:$B$18,2,FALSE),"") -> 10
A9: Amadú Embaló | B9: Armador de Ferro | C9: =IFERROR(VLOOKUP(B9,CONFIG!$A$11:$B$18,2,FALSE),"") -> 12
A10: André Ferreira da Silva Lima | B10: Servente | C10: =IFERROR(VLOOKUP(B10,CONFIG!$A$11:$B$18,2,FALSE),"") -> 8
A11: Carlos Manuel Tavares Monteiro | B11: Servente | C11: =IFERROR(VLOOKUP(B11,CONFIG!$A$11:$B$18,2,FALSE),"") -> 8
A12: Carlos Sequeira | B12: Servente | C12: =IFERROR(VLOOKUP(B12,CONFIG!$A$11:$B$18,2,FALSE),"") -> 8
A13: Correia Agostinho | B13: Pedreiro | C13: =IFERROR(VLOOKUP(B13,CONFIG!$A$11:$B$18,2,FALSE),"") -> 8
A14: Denzel Alridi de Sousa Salé | B14: Servente | C14: =IFERROR(VLOOKUP(B14,CONFIG!$A$11:$B$18,2,FALSE),"") -> 8
A15: Derivaldo Manuel | B15: Servente | C15: =IFERROR(VLOOKUP(B15,CONFIG!$A$11:$B$18,2,FALSE),"") -> 8
... A39: Tiago Pereira Queirós | B39: Servente | C39: =IFERROR(VLOOKUP(B39,CONFIG!$A$11:$B$18,2,FALSE),"") -> 8

Sheet REGISTOS_POR_DIA
A1: DATA_ARQUIVO | B1: DATA_REGISTO | C1: Nome | D1: Função | E1: Obra | F1: Fase de Obra | G1: Horas | H1: Atraso_Minutos | I1: Falta | J1: Motivo Falta | K1: €/h | L1: Custo Dia (€) | M1: Observação | N1: ID_Registo
A2: 46071 | B2: 46071 | C2: Admilson Ramos | D2: Polivalente | E2: Pera I | F2: E - paredes exteriores e interiores | G2: 8 | I2: FALSE | K2: 8 | L2: 64 | N2: 57d473f3
A3: 46072 | B3: 46072 | C3: Agmarlo de Albuquerque Ambrósio | D3: Polivalente | E3: Pera I | F3: F - capoto/isolamento | G3: 8 | I3: FALSE | K3: 8 | L3: 64 | N3: c3ba656e
A4: 46072 | B4: 46072 | C4: Molungi Artur | D4: Servente | E4: Pera I | F4: G- eletricidade | G4: 8 | I4: FALSE | K4: 8 | L4: 64 | N4: 492fce10
A5: 46072 | B5: 46072 | C5: Afonso Rodrigo Silva | D5: Servente | E5: Pera II | F5: F - capoto/isolamento | G5: 8 | I5: FALSE | K5: 8 | L5: 64 | N5: 938b5037
A6: 46072 | B6: 46072 | C6: Amadú Embaló | D6: Armador de Ferro | E6: Pera II | F6: E - paredes exteriores e interiores | G6: 8 | I6: FALSE | K6: 8 | L6: 64 | N6: 9cc2d133
A7: 46072 | B7: 46072 | C7: Abigail Alexandrino | D7: Servente | E7: Pera II | F7: D - estrutura | G7: 8 | I7: FALSE | K7: 8 | L7: 64 | N7: 36848838
A8: 46072 | B8: 46072 | C8: Derivaldo Manuel | D8: Servente | E8: Montijo | F8: G- eletricidade | G8: 8 | I8: FALSE | K8: 8 | L8: 64 | N8: bda023ef
A9: 46072 | B9: 46072 | C9: João Carlos Gonçalves Semedo | D9: Carpinteiro de cofragem | E9: Montijo | F9: F - capoto/isolamento | G9: 8 | I9: TRUE | J9: Injustificada | K9: 8 | L9: 0 | N9: a4a994c7
A10: 46072 | B10: 46072 | C10: Admilson Ramos | D10: Polivalente | E10: Palmela | F10: E - paredes exteriores e interiores | G10: 7 | I10: FALSE | K10: 8 | L10: 56 | N10: 41219344
A11: 46072 | B11: 46072 | C11: Kambungo Jeremias | D11: Servente | E11: Palmela | F11: D - estrutura | G11: 8 | I11: TRUE | J11: Baixa | K11: 8 | L11: 0 | N11: 75698db4
A12: 46073 | B12: 46073 | C12: Admilson Ramos | D12: Polivalente | E12: Pera I | F12: E - paredes exteriores e interiores | G12: 4 | I12: FALSE | K12: 8 | L12: 32 | N12: ae67f2bd
A13: 46073 | B13: 46073 | C13: Admilson Ramos | D13: Polivalente | E13: Pera I | F13: D - estrutura | G13: 1 | I13: FALSE | K13: 8 | L13: 8 | N13: 41fc500e
A14: 46073 | B14: 46073 | C14: Feliciano Costa | D14: Pedreiro | E14: Fernão Ferro I | F14: F - capoto/isolamento | G14: 5 | I14: FALSE | K14: 8 | L14: 40 | N14: a399a35b
A15: 46073 | B15: 46073 | C15: Adriano Mendes | D15: Servente | E15: Fernão Ferro I | F15: G- eletricidade | G15: 5 | I15: FALSE | K15: 8 | L15: 40 | N15: 7f8fdc17
A16: 46073 | B16: 46073 | C16: Agmarlo de Albuquerque Ambrósio | D16: Polivalente | E16: Fernão Ferro I | F16: F - capoto/isolamento | G16: 8 | I16: TRUE | J16: Injustificada | K16: 8 | L16: 0 | N16: 55e17d6c
A17: 46073 | B17: 46073 | C17: Felisberto Fernandes | D17: Carpinteiro de cofragem | E17: Fernão Ferro I | F17: M - pavimentos | G17: 7 | I17: FALSE | K17: 8 | L17: 56 | N17: 6a2e6542
A18: 46073 | B18: 46073 | C18: Afonso Rodrigo Silva | D18: Servente | E18: Pera I | F18: U / M - janelas/caixilharias | G18: 8 | I18: FALSE | K18: 8 | L18: 64 | N18: f522bbbc
A19: 46073 | B19: 46073 | C19: Carlos Sequeira | D19: Servente | E19: Pera II | F19: D - estrutura | G19: 8 | I19: FALSE | K19: 8 | L19: 64 | N19: 5b901d46
A20: 46073 | B20: 46073 | C20: Adriano Mendes | D20: Servente | E20: Pera II | F20: F - capoto/isolamento | G20: 1 | I20: FALSE | K20: 8 | L20: 8 | N20: 7f4dafa9
A21: 46074 | B21: 46074 | C21: Admilson Ramos | D21: Polivalente | E21: Pera I | F21: E - paredes exteriores e interiores | G21: 4 | I21: FALSE | K21: 8 | L21: 32 | N21: 19bf10eb
A22: 46074 | B22: 46074 | C22: Admilson Ramos | D22: Polivalente | E22: Pera I | F22: D - estrutura | G22: 1 | I22: FALSE | K22: 8 | L22: 8 | N22: 11597d9f
A23: 46074 | B23: 46074 | C23: Afonso Rodrigo Silva | D23: Servente | E23: Pera I | F23: U / M - janelas/caixilharias | G23: 8 | I23: FALSE | K23: 8 | L23: 64 | N23: 7e6f1cac
A24: 46074 | B24: 46074 | C24: Carlos Sequeira | D24: Servente | E24: Pera II | F24: D - estrutura | G24: 8 | I24: FALSE | K24: 8 | L24: 64 | N24: 14123995
A25: 46074 | B25: 46074 | C25: Adriano Mendes | D25: Servente | E25: Pera II | F25: F - capoto/isolamento | G25: 1 | I25: FALSE | K25: 8 | L25: 8 | N25: 90c459ae
A26: 46074 | B26: 46074 | C26: João Carlos Gonçalves Semedo | D26: Carpinteiro de cofragem | E26: Sintra | F26: D - estrutura | G26: 8 | I26: FALSE | K26: 8 | L26: 64 | N26: f5f4739b
A27: 46074 | B27: 46074 | C27: Matheus Amaral | D27: Servente | E27: Sintra | F27: F - capoto/isolamento | G27: 8 | I27: FALSE | K27: 8 | L27: 64 | N27: aeb1b9e5
A28: 46074 | B28: 46074 | C28: Luizinho Raúl Tingo | D28: Servente | E28: Sintra | F28: G- eletricidade | G28: 8 | I28: TRUE | J28: Férias | K28: 8 | L28: 0 | N28: f49e9f7a
A29: 46074 | B29: 46074 | C29: Denzel Alridi de Sousa Salé | D29: Servente | E29: Pera I | F29: F - capoto/isolamento | G29: 8 | I29: FALSE | K29: 8 | L29: 64 | N29: c81c8538
A30: 46075 | B30: 46075 | C30: Carlos Sequeira | D30: Servente | E30: Pera II | F30: D - estrutura | G30: 8 | I30: FALSE | K30: 8 | L30: 64 | N30: de285147
A31: 46075 | B31: 46075 | C31: Adriano Mendes | D31: Servente | E31: Pera II | F31: F - capoto/isolamento | G31: 1 | I31: FALSE | K31: 8 | L31: 8 | N31: df2c0c41
A32: 46075 | B32: 46075 | C32: Derivaldo Manuel | D32: Servente | E32: Montijo | F32: G- eletricidade | G32: 8 | I32: FALSE | K32: 8 | L32: 64 | N32: 55aa35f5
A33: 46075 | B33: 46075 | C33: João Carlos Gonçalves Semedo | D33: Carpinteiro de cofragem | E33: Montijo | F33: F - capoto/isolamento | G33: 8 | I33: FALSE | K33: 8 | L33: 64 | N33: c22430ff
A34: 46075 | B34: 46075 | C34: Admilson Ramos | D34: Polivalente | E34: Palmela | F34: E - paredes exteriores e interiores | G34: 7 | I34: FALSE | K34: 8 | L34: 56 | N34: 300adfd9
A35: 46075 | B35: 46075 | C35: Kambungo Jeremias | D35: Servente | E35: Palmela | F35: D - estrutura | G35: 8 | I35: FALSE | K35: 8 | L35: 64 | N35: 95bc8372
A36: 46076 | B36: 46076 | C36: Derivaldo Manuel | D36: Servente | E36: Montijo | F36: G- eletricidade | G36: 8 | I36: FALSE | K36: 8 | L36: 64 | N36: 3ee10d16
A37: 46076 | B37: 46076 | C37: João Carlos Gonçalves Semedo | D37: Carpinteiro de cofragem | E37: Montijo | F37: F - capoto/isolamento | G37: 8 | I37: FALSE | K37: 8 | L37: 64 | N37: 5e27c26f
A38: 46076 | B38: 46076 | C38: Admilson Ramos | D38: Polivalente | E38: Pera I | F38: E - paredes exteriores e interiores | G38: 4 | I38: FALSE | K38: 8 | L38: 32 | N38: 7eb2a7db
A39: 46076 | B39: 46076 | C39: Admilson Ramos | D39: Polivalente | E39: Pera I | F39: D - estrutura | G39: 1 | I39: FALSE | K39: 8 | L39: 8 | N39: 94ae2ef0
A40: 46076 | B40: 46076 | C40: Afonso Rodrigo Silva | D40: Servente | E40: Pera I | F40: U / M - janelas/caixilharias | G40: 8 | I40: FALSE | K40: 8 | L40: 64 | N40: c2243132
...

Sheet AUDIT_LOG
A1: ID_Log | B1: Data_Hora | C1: Utilizador | D1: Operacao | E1: Tabela_Alvo | F1: ID_Alvo | G1: Estado_Anterior | H1: Estado_Novo
A2: 751f84fb | B2: 02/20/2026 10:43:29 | C2: seguros.manuelteles@gmail.com | D2: Edição/Remoção | E2: REGISTOS_POR_DIA | F2: 7bdceede | G2: Nome: Admilson Ramos | Obra: Pera I | Fase: E - paredes exteriores e interiores | Horas: 8 | Falta: N | H2: Nome: Admilson Ramos | Obra: Pera I | Fase: G- eletricidade | Horas: 6 | Falta: N
A3: 2dedf7da | B3: 02/20/2026 10:44:34 | C3: seguros.manuelteles@gmail.com | D3: Edição/Remoção | E3: REGISTOS_POR_DIA | F3: 7bdceede | G3: Nome: Admilson Ramos | Obra: Pera I | Fase: G- eletricidade | Horas: 6 | Falta: N | H3: Nome: Admilson Ramos | Obra: Pera I | Fase: G- eletricidade | Horas: 6 | Falta: Y | Motivo: Injustificada
A4: 692bdb85 | B4: 02/20/2026 10:45:09 | C4: seguros.manuelteles@gmail.com | D4: Edição/Remoção | E4: REGISTOS_POR_DIA | F4: 7bdceede | G4: Nome: Admilson Ramos | Obra: Pera I | Fase: G- eletricidade | Horas: 6 | Falta: Y | Motivo: Injustificada | H4: Nome: Admilson Ramos | Obra: Pera I | Fase: G- eletricidade | Horas: 6 | Falta: Y | Motivo: Injustificada | Obs: Mentiu
A5: bbc8b51c | B5: 02/20/2026 10:53:20 | C5: seguros.manuelteles@gmail.com | D5: Edição/Remoção | E5: REGISTOS_POR_DIA | F5: b1164502 | G5: Nome: Molungi Artur | Obra: Pera I | Fase: D - estrutura | Horas: 5 | Falta: N | Obs: abc | H5: Nome: Igor Leite | Obra: Pera I | Fase: D - estrutura | Horas: 5 | Falta: N | Obs: abc
A6: 858964ab | B6: 02/20/2026 11:11:58 | C6: seguros.manuelteles@gmail.com | D6: Edição/Remoção | E6: REGISTOS_POR_DIA | F6: 20b36efe | G6: Nome: Amadú Embaló | Obra: Pera II | Fase: E - paredes exteriores e interiores | Horas: 8 | Falta: N | H6: Nome: Amadú Embaló | Obra: Pera II | Fase: E - paredes exteriores e interiores | Horas: 4 | Falta: N
A7: b5cd3b10 | B7: 02/20/2026 11:15:10 | C7: seguros.manuelteles@gmail.com | D7: Edição/Remoção | E7: REGISTOS_POR_DIA | F7: d12e7786 | G7: Nome: Amadú Embaló | Obra: Sintra | Fase: H- aguas | Horas: 4 | Falta: N | Obs: Abc | H7: Nome: Amadú Embaló | Obra: Sintra | Fase: H- aguas | Horas: 4 | Falta: N | Obs: Abfhgf
A8: 75605a7a | B8: 02/20/2026 12:53:04 | C8: seguros.manuelteles@gmail.com | D8: Edição/Remoção | E8: REGISTOS_POR_DIA | F8: 0c38100e | G8: Nome: Derivaldo Manuel | Obra: Montijo | Fase: G- eletricidade | Horas: 8 | Falta: N | H8: Nome: | Obra: | Fase: | Horas: | Falta:
A9: 9f81e486 | B9: 02/20/2026 13:51:19 | C9: seguros.manuelteles@gmail.com | D9: Edição/Remoção | E9: REGISTOS_POR_DIA | F9: ee8a7ce2 | G9: Nome: Afonso Rodrigo Silva | Obra: Pera II | Fase: F - capoto/isolamento | Horas: 8 | Falta: N | H9: Nome: | Obra: | Fase: | Horas: | Falta:
A10: f445ab0c | B10: 02/20/2026 13:51:22 | C10: seguros.manuelteles@gmail.com | D10: Edição/Remoção | E10: REGISTOS_POR_DIA | F10: 20b36efe | G10: Nome: Amadú Embaló | Obra: Pera II | Fase: E - paredes exteriores e interiores | Horas: 4 | Falta: N | H10: Nome: | Obra: | Fase: | Horas: | Falta:
A11: 7a76b491 | B11: 02/20/2026 13:51:25 | C11: seguros.manuelteles@gmail.com | D11: Edição/Remoção | E11: REGISTOS_POR_DIA | F11: 812a3893 | G11: Nome: Abigail Alexandrino | Obra: Pera II | Fase: D - estrutura | Horas: 8 | Falta: N | H11: Nome: | Obra: | Fase: | Horas: | Falta:
A12: c3e18be3 | B12: 02/20/2026 13:51:28 | C12: seguros.manuelteles@gmail.com | D12: Edição/Remoção | E12: REGISTOS_POR_DIA | F12: caf445cc | G12: Nome: Molungi Artur | Obra: Pera II | Fase: D - estrutura | Horas: 3 | Falta: N | H12: Nome: | Obra: | Fase: | Horas: | Falta:
... A31: 7eef6b50 | B31: 02/24/2026 13:14:46 | C31: seguros.manuelteles@gmail.com | D31: ADICIONAR | E31: REGISTOS_POR_DIA | F31: f3a728f7 | G31: --- NOVO REGISTO (Criação) --- | H31: Nome: André Ferreira da Silva Lima | Obra: Oeiras | Fase: B - abertura estaleiro | Horas: 8 | Falta: N

Sheet MATRIZ_ROTAS
A1: Origem | B1: Destino | C1: Custo_Euro
A2: Pera I | B2: Pera I | C2: 0
A3: Pera I | B3: Pera II | C3: 0
A4: Pera I | B4: Fernão Ferro I | C4: 10
A5: Pera I | B5: Fernão Ferro II | C5: 10
A6: Pera I | B6: Sobreda | C6: 10
A7: Pera I | B7: Montijo | C7: 20
A8: Pera I | B8: Palmela | C8: 20
A9: Pera I | B9: Lagoa de Albufeira | C9: 10
A10: Pera I | B10: Sintra | C10: 20
A11: Pera I | B11: Oeiras | C11: 15
A12: Pera I | B12: Qta da Queimada | C12: 10
A13: Pera I | B13: Conde da Cunha | C13: 15
... A257: Setúbal | B257: Setúbal | C257: 0

Sheet REGISTO_DESLOCACOES
A1: ID_Viagem | B1: Data | C1: Obra_Destino | D1: Origem | E1: Quantidade_Viagens | F1: Custo_Total
A2: 85e5daed | B2: 46076 | C2: Pera I | D2: Fernão Ferro I | E2: 3 | F2: 30
A3: 0df4e66f | B3: 46076 | C3: Pera I | D3: Setúbal | E3: 2 | F3: 50
A4: 89f5e971 | B4: 46076 | C4: Pera II | D4: Fernão Ferro I | E4: 1 | F4: 10
A5: 4919f76d | B5: 46076 | D5: Oeiras | E5: 1 | F5: 0
A6: e2e947d6 | B6: 46076 | C6: Fernão Ferro II | D6: Fernão Ferro I | E6: 1 | F6: 0
A7: e1caa206 | B7: 46076 | C7: Fernão Ferro I | D7: Sintra | E7: 2 | F7: 40
A8: 221d67a1 | B8: 46076 | C8: Sintra | D8: Pera II | E8: 1 | F8: 20
A9: f6124436 | B9: 46076 | C9: Palmela | D9: Fernão Ferro I | E9: 1 | F9: 15
A10: 32b518b8 | B10: 46076 | C10: Pera II | D10: Montijo | E10: 2 | F10: 40
A11: 0d8481e4 | B11: 46076 | C11: Pera II | D11: Palmela | E11: 1 | F11: 20
